2020-02-03 12:21:00,070 INFO: Microblog startup [in /home/v.kovalov/projects/flask_01_2020/app/__init__.py:51]
2020-02-03 12:22:59,353 INFO: Microblog startup [in /home/v.kovalov/projects/flask_01_2020/app/__init__.py:52]
2020-02-03 12:49:53,117 INFO: Microblog startup [in /home/v.kovalov/projects/flask_01_2020/app/__init__.py:52]
2020-02-03 12:50:09,523 INFO: Microblog startup [in /home/v.kovalov/projects/flask_01_2020/app/__init__.py:52]
2020-02-03 14:52:59,355 INFO: Microblog startup [in /home/v.kovalov/projects/flask_01_2020/app/__init__.py:52]
2020-02-03 15:02:45,867 INFO: Microblog startup [in /home/v.kovalov/projects/flask_01_2020/app/__init__.py:52]
2020-02-03 15:02:50,417 INFO: Microblog startup [in /home/v.kovalov/projects/flask_01_2020/app/__init__.py:52]
2020-02-03 15:25:12,987 INFO: Microblog startup [in /home/v.kovalov/projects/flask_01_2020/app/__init__.py:52]
2020-02-03 15:25:44,259 INFO: Microblog startup [in /home/v.kovalov/projects/flask_01_2020/app/__init__.py:52]
2020-02-03 15:56:00,468 INFO: Microblog startup [in /home/v.kovalov/projects/flask_01_2020/app/__init__.py:52]
2020-02-03 15:56:03,002 ERROR: Exception on / [GET] [in /home/v.kovalov/projects/flask_01_2020/venv/lib/python3.6/site-packages/flask/app.py:1891]
Traceback (most recent call last):
  File "/home/v.kovalov/projects/flask_01_2020/venv/lib/python3.6/site-packages/flask/app.py", line 2446, in wsgi_app
    response = self.full_dispatch_request()
  File "/home/v.kovalov/projects/flask_01_2020/venv/lib/python3.6/site-packages/flask/app.py", line 1951, in full_dispatch_request
    rv = self.handle_user_exception(e)
  File "/home/v.kovalov/projects/flask_01_2020/venv/lib/python3.6/site-packages/flask/app.py", line 1820, in handle_user_exception
    reraise(exc_type, exc_value, tb)
  File "/home/v.kovalov/projects/flask_01_2020/venv/lib/python3.6/site-packages/flask/_compat.py", line 39, in reraise
    raise value
  File "/home/v.kovalov/projects/flask_01_2020/venv/lib/python3.6/site-packages/flask/app.py", line 1949, in full_dispatch_request
    rv = self.dispatch_request()
  File "/home/v.kovalov/projects/flask_01_2020/venv/lib/python3.6/site-packages/flask/app.py", line 1935, in dispatch_request
    return self.view_functions[rule.endpoint](**req.view_args)
  File "/home/v.kovalov/projects/flask_01_2020/venv/lib/python3.6/site-packages/flask_login/utils.py", line 261, in decorated_view
    return func(*args, **kwargs)
  File "/home/v.kovalov/projects/flask_01_2020/app/routes.py", line 25, in index
    page, app.config['POSTS_PER_PAGE'], False)
KeyError: 'POSTS_PER_PAGE'
2020-02-03 16:00:14,946 INFO: Microblog startup [in /home/v.kovalov/projects/flask_01_2020/app/__init__.py:52]
2020-02-03 16:07:05,975 ERROR: Exception on /explore [GET] [in /home/v.kovalov/projects/flask_01_2020/venv/lib/python3.6/site-packages/flask/app.py:1891]
Traceback (most recent call last):
  File "/home/v.kovalov/projects/flask_01_2020/venv/lib/python3.6/site-packages/flask/app.py", line 2446, in wsgi_app
    response = self.full_dispatch_request()
  File "/home/v.kovalov/projects/flask_01_2020/venv/lib/python3.6/site-packages/flask/app.py", line 1951, in full_dispatch_request
    rv = self.handle_user_exception(e)
  File "/home/v.kovalov/projects/flask_01_2020/venv/lib/python3.6/site-packages/flask/app.py", line 1820, in handle_user_exception
    reraise(exc_type, exc_value, tb)
  File "/home/v.kovalov/projects/flask_01_2020/venv/lib/python3.6/site-packages/flask/_compat.py", line 39, in reraise
    raise value
  File "/home/v.kovalov/projects/flask_01_2020/venv/lib/python3.6/site-packages/flask/app.py", line 1949, in full_dispatch_request
    rv = self.dispatch_request()
  File "/home/v.kovalov/projects/flask_01_2020/venv/lib/python3.6/site-packages/flask/app.py", line 1935, in dispatch_request
    return self.view_functions[rule.endpoint](**req.view_args)
  File "/home/v.kovalov/projects/flask_01_2020/venv/lib/python3.6/site-packages/flask_login/utils.py", line 261, in decorated_view
    return func(*args, **kwargs)
  File "/home/v.kovalov/projects/flask_01_2020/app/routes.py", line 45, in explore
    next_url=next_url, prev_url=prev_url)
  File "/home/v.kovalov/projects/flask_01_2020/venv/lib/python3.6/site-packages/flask/templating.py", line 140, in render_template
    ctx.app,
  File "/home/v.kovalov/projects/flask_01_2020/venv/lib/python3.6/site-packages/flask/templating.py", line 120, in _render
    rv = template.render(context)
  File "/home/v.kovalov/projects/flask_01_2020/venv/lib/python3.6/site-packages/jinja2/environment.py", line 1090, in render
    self.environment.handle_exception()
  File "/home/v.kovalov/projects/flask_01_2020/venv/lib/python3.6/site-packages/jinja2/environment.py", line 832, in handle_exception
    reraise(*rewrite_traceback_stack(source=source))
  File "/home/v.kovalov/projects/flask_01_2020/venv/lib/python3.6/site-packages/jinja2/_compat.py", line 28, in reraise
    raise value.with_traceback(tb)
  File "/home/v.kovalov/projects/flask_01_2020/app/templates/index.html", line 1, in top-level template code
    {% extends "base.html" %}
  File "/home/v.kovalov/projects/flask_01_2020/app/templates/base.html", line 31, in top-level template code
    {% block content %}{% endblock %}
  File "/home/v.kovalov/projects/flask_01_2020/app/templates/index.html", line 21, in block "content"
    {% include '_post.html' %}
  File "/home/v.kovalov/projects/flask_01_2020/app/templates/_post.html", line 3, in top-level template code
    <td><img src="{{ post.author.avatar(36) }}"></td>
jinja2.exceptions.UndefinedError: 'None' has no attribute 'avatar'
2020-02-03 16:12:19,572 INFO: Microblog startup [in /home/v.kovalov/projects/flask_01_2020/app/__init__.py:52]
2020-02-03 16:34:42,371 INFO: Microblog startup [in /home/v.kovalov/projects/flask_01_2020/app/__init__.py:54]
2020-02-04 10:38:30,662 INFO: Microblog startup [in /home/v.kovalov/projects/flask_01_2020/app/__init__.py:57]
2020-02-04 10:39:22,778 INFO: Microblog startup [in /home/v.kovalov/projects/flask_01_2020/app/__init__.py:57]
2020-02-04 10:40:50,028 INFO: Microblog startup [in /home/v.kovalov/projects/flask_01_2020/app/__init__.py:57]
2020-02-04 10:48:51,428 INFO: Microblog startup [in /home/v.kovalov/projects/flask_01_2020/app/__init__.py:57]
2020-02-04 10:48:55,640 ERROR: Exception on /index [GET] [in /home/v.kovalov/projects/flask_01_2020/venv/lib/python3.6/site-packages/flask/app.py:1891]
Traceback (most recent call last):
  File "/home/v.kovalov/projects/flask_01_2020/venv/lib/python3.6/site-packages/flask/app.py", line 2446, in wsgi_app
    response = self.full_dispatch_request()
  File "/home/v.kovalov/projects/flask_01_2020/venv/lib/python3.6/site-packages/flask/app.py", line 1951, in full_dispatch_request
    rv = self.handle_user_exception(e)
  File "/home/v.kovalov/projects/flask_01_2020/venv/lib/python3.6/site-packages/flask/app.py", line 1820, in handle_user_exception
    reraise(exc_type, exc_value, tb)
  File "/home/v.kovalov/projects/flask_01_2020/venv/lib/python3.6/site-packages/flask/_compat.py", line 39, in reraise
    raise value
  File "/home/v.kovalov/projects/flask_01_2020/venv/lib/python3.6/site-packages/flask/app.py", line 1949, in full_dispatch_request
    rv = self.dispatch_request()
  File "/home/v.kovalov/projects/flask_01_2020/venv/lib/python3.6/site-packages/flask/app.py", line 1935, in dispatch_request
    return self.view_functions[rule.endpoint](**req.view_args)
  File "/home/v.kovalov/projects/flask_01_2020/venv/lib/python3.6/site-packages/flask_login/utils.py", line 261, in decorated_view
    return func(*args, **kwargs)
  File "/home/v.kovalov/projects/flask_01_2020/app/routes.py", line 35, in index
    prev_url=prev_url)
  File "/home/v.kovalov/projects/flask_01_2020/venv/lib/python3.6/site-packages/flask/templating.py", line 138, in render_template
    ctx.app.jinja_env.get_or_select_template(template_name_or_list),
  File "/home/v.kovalov/projects/flask_01_2020/venv/lib/python3.6/site-packages/jinja2/environment.py", line 930, in get_or_select_template
    return self.get_template(template_name_or_list, parent, globals)
  File "/home/v.kovalov/projects/flask_01_2020/venv/lib/python3.6/site-packages/jinja2/environment.py", line 883, in get_template
    return self._load_template(name, self.make_globals(globals))
  File "/home/v.kovalov/projects/flask_01_2020/venv/lib/python3.6/site-packages/jinja2/environment.py", line 857, in _load_template
    template = self.loader.load(self, name, globals)
  File "/home/v.kovalov/projects/flask_01_2020/venv/lib/python3.6/site-packages/jinja2/loaders.py", line 129, in load
    code = environment.compile(source, name, filename)
  File "/home/v.kovalov/projects/flask_01_2020/venv/lib/python3.6/site-packages/jinja2/environment.py", line 638, in compile
    self.handle_exception(source=source_hint)
  File "/home/v.kovalov/projects/flask_01_2020/venv/lib/python3.6/site-packages/jinja2/environment.py", line 832, in handle_exception
    reraise(*rewrite_traceback_stack(source=source))
  File "/home/v.kovalov/projects/flask_01_2020/venv/lib/python3.6/site-packages/jinja2/_compat.py", line 28, in reraise
    raise value.with_traceback(tb)
  File "/home/v.kovalov/projects/flask_01_2020/app/templates/index.html", line 37, in template
    {% endif %}
jinja2.exceptions.TemplateSyntaxError: Encountered unknown tag 'endif'. Jinja was looking for the following tags: 'endblock'. The innermost block that needs to be closed is 'block'.
2020-02-04 10:49:29,342 INFO: Microblog startup [in /home/v.kovalov/projects/flask_01_2020/app/__init__.py:57]
2020-02-04 10:53:05,856 INFO: Microblog startup [in /home/v.kovalov/projects/flask_01_2020/app/__init__.py:57]
2020-02-04 11:23:55,222 INFO: Microblog startup [in /home/v.kovalov/projects/flask_01_2020/app/__init__.py:59]
2020-02-04 11:25:13,193 INFO: Microblog startup [in /home/v.kovalov/projects/flask_01_2020/app/__init__.py:59]
2020-02-04 11:28:55,054 INFO: Microblog startup [in /home/v.kovalov/projects/flask_01_2020/app/__init__.py:59]
2020-02-04 11:29:26,227 INFO: Microblog startup [in /home/v.kovalov/projects/flask_01_2020/app/__init__.py:59]
